<?xml version="1.0" ?>
<!-- =================================================================================== -->
<!-- |    This document was autogenerated by xacro from tom_3d.urdf.xacro              | -->
<!-- |    EDITING THIS FILE BY HAND IS NOT RECOMMENDED                                 | -->
<!-- =================================================================================== -->
<robot name="tom_3d" xmlns:xacro="http://www.ros.org/wiki/xacro">
  <!--GAZEBO REFERENCES -->
  <gazebo>
    <plugin filename="libgazebo_ros_control.so" name="gazebo_ros_control">
      <robotNamespace>/tom_3d</robotNamespace>
      <robotParam>/robot_description</robotParam>
      <robotSimType>gazebo_ros_control/DefaultRobotHWSim</robotSimType>
    </plugin>
  </gazebo>
  <gazebo reference="base_link">
    <material value="Gazebo/Grey"/>
  </gazebo>
  <gazebo reference="left_wheel_link">
    <material value="Gazebo/Black"/>
  </gazebo>
  <gazebo reference="right_wheel_link">
    <gravity>true</gravity>
    <self_collide>false</self_collide>
    <material value="Gazebo/Black"/>
  </gazebo>
  <gazebo reference="caster_frame_link">
    <mu1>0.0</mu1>
    <mu2>0.0</mu2>
    <kp>1000000.0</kp>
    <kd>100.0</kd>
    <minDepth>0.001</minDepth>
    <maxVel>1.0</maxVel>
    <material value="Gazebo/Grey"/>
  </gazebo>
  <gazebo reference="caster_wheel_link">
    <mu1>0.0</mu1>
    <mu2>0.0</mu2>
    <kp>1000000.0</kp>
    <kd>100.0</kd>
    <minDepth>0.001</minDepth>
    <maxVel>1.0</maxVel>
    <material value="Gazebo/Black"/>
  </gazebo>
  <gazebo reference="sick_pls_link">
    <material value="Gazebo/Yellow"/>
    <sensor name="sick_pls_sensor" type="ray">
      <pose>0 0 0 0 0 0</pose>
      <visualize>true</visualize>
      <update_rate>40</update_rate>
      <ray>
        <scan>
          <horizontal>
            <samples>720</samples>
            <resolution>1</resolution>
            <min_angle>-1.57</min_angle>
            <max_angle>1.57</max_angle>
          </horizontal>
        </scan>
        <range>
          <min>0.10</min>
          <max>30.0</max>
          <resolution>0.05</resolution>
        </range>
        <noise>
          <type>gaussian</type>
          <mean>0.0</mean>
          <stddev>0.01</stddev>
        </noise>
      </ray>
      <plugin filename="libgazebo_ros_laser.so" name="sick_pls">
        <topicName>sick_pls/scan</topicName>
        <frameName>sick_pls_link</frameName>
      </plugin>
    </sensor>
  </gazebo>
  <gazebo>
    <plugin filename="libgazebo_ros_diff_drive.so" name="differential_drive_controller">
      <robotNamespace>/</robotNamespace>
      <alwaysOn>true</alwaysOn>
      <updateRate>100.0</updateRate>
      <leftJoint>left_wheel_joint</leftJoint>
      <rightJoint>right_wheel_joint</rightJoint>
      <wheelTorque>20</wheelTorque>
      <legacyMode>false</legacyMode>
      <wheelSeparation>0.3068</wheelSeparation>
      <wheelDiameter>0.15</wheelDiameter>
      <torque>20</torque>
      <commandTopic>/cmd_vel</commandTopic>
      <odometryTopic>/odom</odometryTopic>
      <odometryFrame>/odom</odometryFrame>
      <robotBaseFrame>/base_link</robotBaseFrame>
      <rosDebugLevel>na</rosDebugLevel>
      <rosDebugLevel>false</rosDebugLevel>
      <rosDebugLevel>Debug</rosDebugLevel>
      <publishWheelTF>true</publishWheelTF>
      <publishWheelJointState>true</publishWheelJointState>
      <wheelAcceleration>0.4</wheelAcceleration>
      <publishTf>1</publishTf>
      <odometrySource>encoder</odometrySource>
    </plugin>
  </gazebo>
  <transmission name="left_wheel_trans">
    <type>transmission_interface/SimpleTransmission</type>
    <robotNamespace>tom_3d</robotNamespace>
    <joint name="left_wheel_joint">
      <hardwareInterface>EffortJointInterface</hardwareInterface>
    </joint>
    <actuator name="right_wheel_motor">
      <mechanicalReduction>1</mechanicalReduction>
    </actuator>
  </transmission>
  <transmission name="left_wheel_trans">
    <type>transmission_interface/SimpleTransmission</type>
    <robotNamespace>tom_3d</robotNamespace>
    <joint name="right_wheel_joint">
      <hardwareInterface>EffortJointInterface</hardwareInterface>
    </joint>
    <actuator name="right_wheel_motor">
      <mechanicalReduction>1</mechanicalReduction>
    </actuator>
  </transmission>
  <!-- MATERIALS -->
  <material name="tom_3d/Black">
    <color rgba="0.0 0.0 0.0 1.0"/>
  </material>
  <material name="tom_3d/Blue">
    <color rgba="0.0 0.0 0.8 1.0"/>
  </material>
  <material name="tom_3d/Green">
    <color rgba="0.0 0.8 0.0 1.0"/>
  </material>
  <material name="tom_3d/Grey">
    <color rgba="0.7 0.7 0.7 1.0"/>
  </material>
  <material name="tom_3d/Grey2">
    <color rgba="0.9 0.9 0.9 1.0"/>
  </material>
  <material name="tom_3d/Red">
    <color rgba="0.8 0.0 0.0 1.0"/>
  </material>
  <material name="tom_3d/White">
    <color rgba="1.0 1.0 1.0 1.0"/>
  </material>
  <material name="tom_3d/Yellow">
    <color rgba="1.0 1.0 0 10"/>
  </material>
  <!-- BODY -->
  <!-- WHEELS -->
  <!-- WHEELS -->
  <!-- SENSORS -->
  <!-- CASTER WHEELS -->
  <!-- IMU -->
  <!-- STEREO CAMERA -->
  <!-- Base Macro-->
  <link name="base_link">
    <inertial>
      <origin rpy="0 0 0" xyz="-0.17709 -0.00065294 0.16037"/>
      <mass value="12.377"/>
      <inertia ixx="0.5769" ixy="0.0002763" ixz="-0.041954" iyy="0.58042" iyz="0.0002722" izz="0.1142"/>
    </inertial>
    <visual>
      <origin rpy="0 0 0" xyz="0.08339 0 0.0395"/>
      <geometry>
        <mesh filename="package://tom_3d_simulation/urdf/meshes/base_link.STL"/>
      </geometry>
      <material name="tom_3d/Grey"/>
    </visual>
    <collision>
      <origin rpy="0 0 0" xyz="0 0 0.0395"/>
      <geometry>
        <!--cylinder radius="0.17" length = "0.7" /-->
        <mesh filename="package://tom_3d_simulation/urdf/meshes/base_link.STL"/>
      </geometry>
    </collision>
  </link>
  <!-- Wheel Macro -->
  <joint name="left_wheel_joint" type="continuous">
    <origin rpy="-4.2563E-44 0 0" xyz="-0.00076 0.1534 0.075"/>
    <axis xyz="0 1 0"/>
    <parent link="base_link"/>
    <child link="left_wheel_link"/>
    <limit effort="30.0" velocity="1.0"/>
    <joint_properties damping="1.0" friction="0.2"/>
  </joint>
  <link name="left_wheel_link" type="wheel">
    <inertial>
      <origin rpy="0 0 0" xyz="-7.2741E-08 7.9842E-09 7.1084E-08"/>
      <mass value="0.47973"/>
      <inertia ixx="0.0008385" ixy="3.881E-10" ixz="-3.4742E-08" iyy="0.0015698" iyz="-1.1674E-09" izz="0.00083856"/>
    </inertial>
    <visual>
      <origin rpy="0 0 0" xyz="0 0 0"/>
      <geometry>
        <mesh filename="package://tom_3d_simulation/urdf/meshes/left_wheel_Link.STL"/>
      </geometry>
      <material name="tom_3d/Black"/>
    </visual>
    <collision>
      <origin rpy="0 0 0" xyz="0 0 0"/>
      <geometry>
        <!--cylinder radius="0.075" length="0.042"/-->
        <mesh filename="package://tom_3d_simulation/urdf/meshes/left_wheel_Link.STL"/>
      </geometry>
    </collision>
  </link>
  <joint name="right_wheel_joint" type="continuous">
    <origin rpy="-4.2563E-44 0 0" xyz="-0.00076 -0.1534 0.075"/>
    <axis xyz="0 1 0"/>
    <parent link="base_link"/>
    <child link="right_wheel_link"/>
    <limit effort="30.0" velocity="1.0"/>
    <joint_properties damping="1.0" friction="0.2"/>
  </joint>
  <link name="right_wheel_link" type="wheel">
    <inertial>
      <origin rpy="0 0 0" xyz="7.2151E-08 -7.9842E-09 7.1683E-08"/>
      <mass value="0.47973"/>
      <inertia ixx="0.0008385" ixy="3.7844E-10" ixz="3.4244E-08" iyy="0.0015698" iyz="1.1706E-09" izz="0.00083856"/>
    </inertial>
    <visual>
      <origin rpy="0 0 0" xyz="0 0 0"/>
      <geometry>
        <mesh filename="package://tom_3d_simulation/urdf/meshes/right_wheel_Link.STL"/>
      </geometry>
      <material name="tom_3d/Black"/>
    </visual>
    <collision>
      <origin rpy="0 0 0" xyz="0 0 0"/>
      <geometry>
        <!--cylinder radius="0.075" length="0.042"/-->
        <mesh filename="package://tom_3d_simulation/urdf/meshes/right_wheel_Link.STL"/>
      </geometry>
    </collision>
  </link>
  <!-- Sensors-->
  <joint name="sick_pls_joint" type="fixed">
    <axis xyz="0 0 0"/>
    <origin rpy="-6.983E-15 -8.3333E-10 2.9167E-09" xyz="0.04839 -0.00057363 0.405"/>
    <parent link="base_link"/>
    <child link="sick_pls_link"/>
  </joint>
  <link name="sick_pls_link" type="laser">
    <inertial>
      <origin rpy="0 0 0" xyz="0.07464 2.9656E-09 0.0005964"/>
      <mass value="4.803"/>
      <inertia ixx="0.022714" ixy="-6.4301E-09" ixz="-0.0016489" iyy="0.022161" iyz="2.6112E-09" izz="0.016889"/>
    </inertial>
    <visual>
      <origin rpy="0 0 0" xyz="-0.12 0 0.03"/>
      <geometry>
        <mesh filename="package://tom_3d_simulation/urdf/meshes/sick_pls_Link.STL"/>
      </geometry>
      <material name="tom_3d/Yellow"/>
    </visual>
    <collision>
      <origin rpy="0 0 0" xyz="-0.12 0 0.03"/>
      <geometry>
        <mesh filename="package://tom_3d_simulation/urdf/meshes/sick_pls_Link.STL"/>
      </geometry>
    </collision>
  </link>
  <!-- Caster Wheel Macro -->
  <link name="caster_frame_link">
    <inertial>
      <origin rpy="0 0 0" xyz="-0.00055887 -0.028892 0.019123"/>
      <mass value="0.075875"/>
      <inertia ixx="7.155E-05" ixy="-1.5111E-06" ixz="6.2761E-07" iyy="5.4831E-05" iyz="1.9534E-05" izz="7.4518E-05"/>
    </inertial>
    <visual>
      <origin rpy="0 0 0" xyz="0 0 0"/>
      <geometry>
        <mesh filename="package://tom_3d_simulation/urdf/meshes/caster_frame_Link.STL"/>
      </geometry>
      <material name="tom_3d/Grey"/>
    </visual>
    <collision>
      <origin rpy="0 0 0" xyz="0 0 0"/>
      <geometry>
        <mesh filename="package://tom_3d_simulation/urdf/meshes/caster_frame_Link.STL"/>
      </geometry>
    </collision>
  </link>
  <joint name="caster_frame_joint" type="continuous">
    <origin rpy="1.5708 6.9774E-15 1.6109" xyz="-0.27411 0 0.102114"/>
    <axis xyz="0 1 0"/>
    <parent link="base_link"/>
    <child link="caster_frame_link"/>
  </joint>
  <link name="caster_wheel_link" type="wheel">
    <inertial>
      <origin rpy="0 0 0" xyz="7.2411E-08 -1.7197E-07 3.4401E-08"/>
      <mass value="0.15248"/>
      <inertia ixx="6.8521E-05" ixy="8.1003E-11" ixz="2.3672E-10" iyy="0.00010566" iyz="-7.8553E-11" izz="6.8522E-05"/>
    </inertial>
    <visual>
      <origin rpy="0 0 0" xyz="0 0 0"/>
      <geometry>
        <mesh filename="package://tom_3d_simulation/urdf/meshes/caster_wheel_Link.STL"/>
      </geometry>
      <material name="tom_3d/Black"/>
    </visual>
    <collision>
      <origin rpy="0 0 0" xyz="0 0 0"/>
      <geometry>
        <mesh filename="package://tom_3d_simulation/urdf/meshes/caster_wheel_Link.STL"/>
      </geometry>
    </collision>
  </link>
  <joint name="caster_wheel_joint" type="continuous">
    <origin rpy="0 0 1.5708" xyz="0 -0.064604 0.034"/>
    <axis xyz="0 -1 0"/>
    <parent link="caster_frame_link"/>
    <child link="caster_wheel_link"/>
  </joint>
  <!-- IMU -->
  <joint name="imu_joint" type="fixed">
    <axis xyz="0 0 0"/>
    <origin xyz="-0.07961 -0.00057363 0.556"/>
    <parent link="base_link"/>
    <child link="imu_link"/>
  </joint>
  <link name="imu_link">
    <inertial>
      <mass value="0.001"/>
      <origin rpy="0 0 0" xyz="0 0 0"/>
      <inertia ixx="0.0001" ixy="0" ixz="0" iyy="0.000001" iyz="0" izz="0.0001"/>
    </inertial>
    <visual>
      <origin rpy="0 0 0" xyz="0 0 0"/>
      <geometry>
        <box size="0.05 0.05 0.01"/>
      </geometry>
      <material name="tom_3d/Blue"/>
    </visual>
    <collision>
      <origin rpy="0 0 0" xyz="0 0 0"/>
      <geometry>
        <box size="0.05 0.05 0.01"/>
      </geometry>
    </collision>
  </link>
  <!-- STEREO CAMERA -->
  <joint name="camera_joint" type="fixed">
    <axis xyz="0 0 0"/>
    <origin xyz="0.03339 -0.00057363 0.586"/>
    <parent link="base_link"/>
    <child link="camera_link"/>
  </joint>
  <link name="camera_link">
    <inertial>
      <mass value="0.001"/>
      <origin rpy="0 0 0" xyz="0 0 0"/>
      <inertia ixx="0.0001" ixy="0" ixz="0" iyy="0.000001" iyz="0" izz="0.0001"/>
    </inertial>
    <visual>
      <origin rpy="0 0 0" xyz="0 0 0"/>
      <geometry>
        <box size="0.07 0.19 0.07"/>
      </geometry>
      <material name="tom_3d/Black"/>
    </visual>
    <collision>
      <origin rpy="0 0 0" xyz="0 0 0"/>
      <geometry>
        <box size="0.07 0.211 0.07"/>
      </geometry>
    </collision>
  </link>
</robot>

